[33mWARNING[0m:  [10-05-2024 01:12:13] chroma_server_nofile is not supported on Windows. chroma_server_nofile will not be set.
[32mINFO[0m:     [10-05-2024 01:12:13] Anonymized telemetry enabled. See                     https://docs.trychroma.com/telemetry for more information.
[36mDEBUG[0m:    [10-05-2024 01:12:13] Starting component System
[36mDEBUG[0m:    [10-05-2024 01:12:13] Starting component OpenTelemetryClient
[36mDEBUG[0m:    [10-05-2024 01:12:13] Starting component SqliteDB
[36mDEBUG[0m:    [10-05-2024 01:12:13] Starting component QuotaEnforcer
[36mDEBUG[0m:    [10-05-2024 01:12:13] Starting component Posthog
[36mDEBUG[0m:    [10-05-2024 01:12:13] Starting component LocalSegmentManager
[36mDEBUG[0m:    [10-05-2024 01:12:13] Starting component SegmentAPI
[32mINFO[0m:     [10-05-2024 01:12:13] Started server process [[36m15624[0m]
[32mINFO[0m:     [10-05-2024 01:12:13] Waiting for application startup.
[32mINFO[0m:     [10-05-2024 01:12:13] Application startup complete.
[32mINFO[0m:     [10-05-2024 01:12:13] Uvicorn running on [1mhttp://localhost:8000[0m (Press CTRL+C to quit)
[32mINFO[0m:     [10-05-2024 09:22:38] Shutting down
[32mINFO[0m:     [10-05-2024 09:22:38] Waiting for application shutdown.
[36mDEBUG[0m:    [10-05-2024 09:22:38] Stopping component System
[36mDEBUG[0m:    [10-05-2024 09:22:38] Stopping component SegmentAPI
[36mDEBUG[0m:    [10-05-2024 09:22:38] Stopping component LocalSegmentManager
[36mDEBUG[0m:    [10-05-2024 09:22:38] Stopping component Posthog
[36mDEBUG[0m:    [10-05-2024 09:22:38] Stopping component QuotaEnforcer
[36mDEBUG[0m:    [10-05-2024 09:22:38] Stopping component SqliteDB
[36mDEBUG[0m:    [10-05-2024 09:22:38] Stopping component OpenTelemetryClient
[32mINFO[0m:     [10-05-2024 09:22:38] Application shutdown complete.
[32mINFO[0m:     [10-05-2024 09:22:38] Finished server process [[36m15624[0m]
[33mWARNING[0m:  [10-05-2024 09:23:53] chroma_server_nofile is not supported on Windows. chroma_server_nofile will not be set.
[32mINFO[0m:     [10-05-2024 09:23:53] Anonymized telemetry enabled. See                     https://docs.trychroma.com/telemetry for more information.
[36mDEBUG[0m:    [10-05-2024 09:23:53] Starting component System
[36mDEBUG[0m:    [10-05-2024 09:23:53] Starting component OpenTelemetryClient
[36mDEBUG[0m:    [10-05-2024 09:23:53] Starting component SqliteDB
[36mDEBUG[0m:    [10-05-2024 09:23:53] Starting component QuotaEnforcer
[36mDEBUG[0m:    [10-05-2024 09:23:53] Starting component Posthog
[36mDEBUG[0m:    [10-05-2024 09:23:53] Starting component LocalSegmentManager
[36mDEBUG[0m:    [10-05-2024 09:23:53] Starting component SegmentAPI
[32mINFO[0m:     [10-05-2024 09:23:53] Started server process [[36m22348[0m]
[32mINFO[0m:     [10-05-2024 09:23:53] Waiting for application startup.
[32mINFO[0m:     [10-05-2024 09:23:53] Application startup complete.
[32mINFO[0m:     [10-05-2024 09:23:53] Uvicorn running on [1mhttp://localhost:8080[0m (Press CTRL+C to quit)
[32mINFO[0m:     [10-05-2024 09:53:24] ::1:32562 - "GET /api/v1/tenants/default_tenant HTTP/1.1" 200
[32mINFO[0m:     [10-05-2024 09:53:24] ::1:32562 - "GET /api/v1/databases/default_database?tenant=default_tenant HTTP/1.1" 200
[31mERROR[0m:    [10-05-2024 09:53:24] type object 'CreateCollection' has no attribute 'model_validate'
Traceback (most recent call last):
  File "C:\Users\Alaa\anaconda3\Lib\site-packages\anyio\streams\memory.py", line 97, in receive
    return self.receive_nowait()
           ^^^^^^^^^^^^^^^^^^^^^
  File "C:\Users\Alaa\anaconda3\Lib\site-packages\anyio\streams\memory.py", line 92, in receive_nowait
    raise WouldBlock
anyio.WouldBlock

During handling of the above exception, another exception occurred:

Traceback (most recent call last):
  File "C:\Users\Alaa\anaconda3\Lib\site-packages\starlette\middleware\base.py", line 159, in call_next
    message = await recv_stream.receive()
              ^^^^^^^^^^^^^^^^^^^^^^^^^^^
  File "C:\Users\Alaa\anaconda3\Lib\site-packages\anyio\streams\memory.py", line 112, in receive
    raise EndOfStream
anyio.EndOfStream

During handling of the above exception, another exception occurred:

Traceback (most recent call last):
  File "C:\Users\Alaa\anaconda3\Lib\site-packages\chromadb\server\fastapi\__init__.py", line 78, in catch_exceptions_middleware
    return await call_next(request)
           ^^^^^^^^^^^^^^^^^^^^^^^^
  File "C:\Users\Alaa\anaconda3\Lib\site-packages\starlette\middleware\base.py", line 165, in call_next
    raise app_exc
  File "C:\Users\Alaa\anaconda3\Lib\site-packages\starlette\middleware\base.py", line 151, in coro
    await self.app(scope, receive_or_disconnect, send_no_error)
  File "C:\Users\Alaa\anaconda3\Lib\site-packages\starlette\middleware\base.py", line 189, in __call__
    with collapse_excgroups():
  File "C:\Users\Alaa\anaconda3\Lib\contextlib.py", line 158, in __exit__
    self.gen.throw(typ, value, traceback)
  File "C:\Users\Alaa\anaconda3\Lib\site-packages\starlette\_utils.py", line 93, in collapse_excgroups
    raise exc
  File "C:\Users\Alaa\anaconda3\Lib\site-packages\starlette\middleware\base.py", line 191, in __call__
    response = await self.dispatch_func(request, call_next)
               ^^^^^^^^^^^^^^^^^^^^^^^^^^^^^^^^^^^^^^^^^^^^
  File "C:\Users\Alaa\anaconda3\Lib\site-packages\chromadb\server\fastapi\__init__.py", line 92, in check_http_version_middleware
    return await call_next(request)
           ^^^^^^^^^^^^^^^^^^^^^^^^
  File "C:\Users\Alaa\anaconda3\Lib\site-packages\starlette\middleware\base.py", line 165, in call_next
    raise app_exc
  File "C:\Users\Alaa\anaconda3\Lib\site-packages\starlette\middleware\base.py", line 151, in coro
    await self.app(scope, receive_or_disconnect, send_no_error)
  File "C:\Users\Alaa\anaconda3\Lib\site-packages\starlette\middleware\exceptions.py", line 65, in __call__
    await wrap_app_handling_exceptions(self.app, conn)(scope, receive, send)
  File "C:\Users\Alaa\anaconda3\Lib\site-packages\starlette\_exception_handler.py", line 64, in wrapped_app
    raise exc
  File "C:\Users\Alaa\anaconda3\Lib\site-packages\starlette\_exception_handler.py", line 53, in wrapped_app
    await app(scope, receive, sender)
  File "C:\Users\Alaa\anaconda3\Lib\site-packages\starlette\routing.py", line 756, in __call__
    await self.middleware_stack(scope, receive, send)
  File "C:\Users\Alaa\anaconda3\Lib\site-packages\starlette\routing.py", line 776, in app
    await route.handle(scope, receive, send)
  File "C:\Users\Alaa\anaconda3\Lib\site-packages\starlette\routing.py", line 297, in handle
    await self.app(scope, receive, send)
  File "C:\Users\Alaa\anaconda3\Lib\site-packages\starlette\routing.py", line 77, in app
    await wrap_app_handling_exceptions(app, request)(scope, receive, send)
  File "C:\Users\Alaa\anaconda3\Lib\site-packages\starlette\_exception_handler.py", line 64, in wrapped_app
    raise exc
  File "C:\Users\Alaa\anaconda3\Lib\site-packages\starlette\_exception_handler.py", line 53, in wrapped_app
    await app(scope, receive, sender)
  File "C:\Users\Alaa\anaconda3\Lib\site-packages\starlette\routing.py", line 72, in app
    response = await func(request)
               ^^^^^^^^^^^^^^^^^^^
  File "C:\Users\Alaa\anaconda3\Lib\site-packages\fastapi\routing.py", line 278, in app
    raw_response = await run_endpoint_function(
                   ^^^^^^^^^^^^^^^^^^^^^^^^^^^^
  File "C:\Users\Alaa\anaconda3\Lib\site-packages\fastapi\routing.py", line 191, in run_endpoint_function
    return await dependant.call(**values)
           ^^^^^^^^^^^^^^^^^^^^^^^^^^^^^^
  File "C:\Users\Alaa\anaconda3\Lib\site-packages\chromadb\telemetry\opentelemetry\__init__.py", line 130, in wrapper
    return await f(*args, **kwargs)
           ^^^^^^^^^^^^^^^^^^^^^^^^
  File "C:\Users\Alaa\anaconda3\Lib\site-packages\chromadb\server\fastapi\__init__.py", line 630, in create_collection
    await to_thread.run_sync(
  File "C:\Users\Alaa\anaconda3\Lib\site-packages\anyio\to_thread.py", line 56, in run_sync
    return await get_async_backend().run_sync_in_worker_thread(
           ^^^^^^^^^^^^^^^^^^^^^^^^^^^^^^^^^^^^^^^^^^^^^^^^^^^^
  File "C:\Users\Alaa\anaconda3\Lib\site-packages\anyio\_backends\_asyncio.py", line 2134, in run_sync_in_worker_thread
    return await future
           ^^^^^^^^^^^^
  File "C:\Users\Alaa\anaconda3\Lib\site-packages\anyio\_backends\_asyncio.py", line 851, in run
    result = context.run(func, *args)
             ^^^^^^^^^^^^^^^^^^^^^^^^
  File "C:\Users\Alaa\anaconda3\Lib\site-packages\chromadb\server\fastapi\__init__.py", line 606, in process_create_collection
    create = CreateCollection.model_validate(orjson.loads(raw_body))
             ^^^^^^^^^^^^^^^^^^^^^^^^^^^^^^^
AttributeError: type object 'CreateCollection' has no attribute 'model_validate'
[32mINFO[0m:     [10-05-2024 09:53:24] ::1:32563 - "POST /api/v1/collections?tenant=default_tenant&database=default_database HTTP/1.1" 500
[32mINFO[0m:     [10-05-2024 12:33:03] Shutting down
[32mINFO[0m:     [10-05-2024 12:33:04] Waiting for application shutdown.
[36mDEBUG[0m:    [10-05-2024 12:33:04] Stopping component System
[36mDEBUG[0m:    [10-05-2024 12:33:04] Stopping component SegmentAPI
[36mDEBUG[0m:    [10-05-2024 12:33:04] Stopping component LocalSegmentManager
[36mDEBUG[0m:    [10-05-2024 12:33:04] Stopping component Posthog
[36mDEBUG[0m:    [10-05-2024 12:33:04] Stopping component QuotaEnforcer
[36mDEBUG[0m:    [10-05-2024 12:33:04] Stopping component SqliteDB
[36mDEBUG[0m:    [10-05-2024 12:33:04] Stopping component OpenTelemetryClient
[32mINFO[0m:     [10-05-2024 12:33:04] Application shutdown complete.
[32mINFO[0m:     [10-05-2024 12:33:04] Finished server process [[36m22348[0m]
[33mWARNING[0m:  [10-05-2024 15:51:37] chroma_server_nofile is not supported on Windows. chroma_server_nofile will not be set.
[32mINFO[0m:     [10-05-2024 15:51:37] Anonymized telemetry enabled. See                     https://docs.trychroma.com/telemetry for more information.
[36mDEBUG[0m:    [10-05-2024 15:51:37] Starting component System
[36mDEBUG[0m:    [10-05-2024 15:51:37] Starting component OpenTelemetryClient
[36mDEBUG[0m:    [10-05-2024 15:51:37] Starting component SqliteDB
[36mDEBUG[0m:    [10-05-2024 15:51:38] Starting component QuotaEnforcer
[36mDEBUG[0m:    [10-05-2024 15:51:38] Starting component Posthog
[36mDEBUG[0m:    [10-05-2024 15:51:38] Starting component LocalSegmentManager
[36mDEBUG[0m:    [10-05-2024 15:51:38] Starting component SegmentAPI
[32mINFO[0m:     [10-05-2024 15:51:38] Started server process [[36m21604[0m]
[32mINFO[0m:     [10-05-2024 15:51:38] Waiting for application startup.
[32mINFO[0m:     [10-05-2024 15:51:38] Application startup complete.
[32mINFO[0m:     [10-05-2024 15:51:38] Uvicorn running on [1mhttp://localhost:8080[0m (Press CTRL+C to quit)
[32mINFO[0m:     [10-05-2024 15:51:51] ::1:2286 - "GET /api/v1/tenants/default_tenant HTTP/1.1" 200
[32mINFO[0m:     [10-05-2024 15:51:51] ::1:2286 - "GET /api/v1/databases/default_database?tenant=default_tenant HTTP/1.1" 200
[31mERROR[0m:    [10-05-2024 15:51:54] type object 'CreateCollection' has no attribute 'model_validate'
Traceback (most recent call last):
  File "C:\Users\Alaa\anaconda3\Lib\site-packages\anyio\streams\memory.py", line 97, in receive
    return self.receive_nowait()
           ^^^^^^^^^^^^^^^^^^^^^
  File "C:\Users\Alaa\anaconda3\Lib\site-packages\anyio\streams\memory.py", line 92, in receive_nowait
    raise WouldBlock
anyio.WouldBlock

During handling of the above exception, another exception occurred:

Traceback (most recent call last):
  File "C:\Users\Alaa\anaconda3\Lib\site-packages\starlette\middleware\base.py", line 159, in call_next
    message = await recv_stream.receive()
              ^^^^^^^^^^^^^^^^^^^^^^^^^^^
  File "C:\Users\Alaa\anaconda3\Lib\site-packages\anyio\streams\memory.py", line 112, in receive
    raise EndOfStream
anyio.EndOfStream

During handling of the above exception, another exception occurred:

Traceback (most recent call last):
  File "C:\Users\Alaa\anaconda3\Lib\site-packages\chromadb\server\fastapi\__init__.py", line 78, in catch_exceptions_middleware
    return await call_next(request)
           ^^^^^^^^^^^^^^^^^^^^^^^^
  File "C:\Users\Alaa\anaconda3\Lib\site-packages\starlette\middleware\base.py", line 165, in call_next
    raise app_exc
  File "C:\Users\Alaa\anaconda3\Lib\site-packages\starlette\middleware\base.py", line 151, in coro
    await self.app(scope, receive_or_disconnect, send_no_error)
  File "C:\Users\Alaa\anaconda3\Lib\site-packages\starlette\middleware\base.py", line 189, in __call__
    with collapse_excgroups():
  File "C:\Users\Alaa\anaconda3\Lib\contextlib.py", line 158, in __exit__
    self.gen.throw(typ, value, traceback)
  File "C:\Users\Alaa\anaconda3\Lib\site-packages\starlette\_utils.py", line 93, in collapse_excgroups
    raise exc
  File "C:\Users\Alaa\anaconda3\Lib\site-packages\starlette\middleware\base.py", line 191, in __call__
    response = await self.dispatch_func(request, call_next)
               ^^^^^^^^^^^^^^^^^^^^^^^^^^^^^^^^^^^^^^^^^^^^
  File "C:\Users\Alaa\anaconda3\Lib\site-packages\chromadb\server\fastapi\__init__.py", line 92, in check_http_version_middleware
    return await call_next(request)
           ^^^^^^^^^^^^^^^^^^^^^^^^
  File "C:\Users\Alaa\anaconda3\Lib\site-packages\starlette\middleware\base.py", line 165, in call_next
    raise app_exc
  File "C:\Users\Alaa\anaconda3\Lib\site-packages\starlette\middleware\base.py", line 151, in coro
    await self.app(scope, receive_or_disconnect, send_no_error)
  File "C:\Users\Alaa\anaconda3\Lib\site-packages\starlette\middleware\exceptions.py", line 65, in __call__
    await wrap_app_handling_exceptions(self.app, conn)(scope, receive, send)
  File "C:\Users\Alaa\anaconda3\Lib\site-packages\starlette\_exception_handler.py", line 64, in wrapped_app
    raise exc
  File "C:\Users\Alaa\anaconda3\Lib\site-packages\starlette\_exception_handler.py", line 53, in wrapped_app
    await app(scope, receive, sender)
  File "C:\Users\Alaa\anaconda3\Lib\site-packages\starlette\routing.py", line 756, in __call__
    await self.middleware_stack(scope, receive, send)
  File "C:\Users\Alaa\anaconda3\Lib\site-packages\starlette\routing.py", line 776, in app
    await route.handle(scope, receive, send)
  File "C:\Users\Alaa\anaconda3\Lib\site-packages\starlette\routing.py", line 297, in handle
    await self.app(scope, receive, send)
  File "C:\Users\Alaa\anaconda3\Lib\site-packages\starlette\routing.py", line 77, in app
    await wrap_app_handling_exceptions(app, request)(scope, receive, send)
  File "C:\Users\Alaa\anaconda3\Lib\site-packages\starlette\_exception_handler.py", line 64, in wrapped_app
    raise exc
  File "C:\Users\Alaa\anaconda3\Lib\site-packages\starlette\_exception_handler.py", line 53, in wrapped_app
    await app(scope, receive, sender)
  File "C:\Users\Alaa\anaconda3\Lib\site-packages\starlette\routing.py", line 72, in app
    response = await func(request)
               ^^^^^^^^^^^^^^^^^^^
  File "C:\Users\Alaa\anaconda3\Lib\site-packages\fastapi\routing.py", line 278, in app
    raw_response = await run_endpoint_function(
                   ^^^^^^^^^^^^^^^^^^^^^^^^^^^^
  File "C:\Users\Alaa\anaconda3\Lib\site-packages\fastapi\routing.py", line 191, in run_endpoint_function
    return await dependant.call(**values)
           ^^^^^^^^^^^^^^^^^^^^^^^^^^^^^^
  File "C:\Users\Alaa\anaconda3\Lib\site-packages\chromadb\telemetry\opentelemetry\__init__.py", line 130, in wrapper
    return await f(*args, **kwargs)
           ^^^^^^^^^^^^^^^^^^^^^^^^
  File "C:\Users\Alaa\anaconda3\Lib\site-packages\chromadb\server\fastapi\__init__.py", line 630, in create_collection
    await to_thread.run_sync(
  File "C:\Users\Alaa\anaconda3\Lib\site-packages\anyio\to_thread.py", line 56, in run_sync
    return await get_async_backend().run_sync_in_worker_thread(
           ^^^^^^^^^^^^^^^^^^^^^^^^^^^^^^^^^^^^^^^^^^^^^^^^^^^^
  File "C:\Users\Alaa\anaconda3\Lib\site-packages\anyio\_backends\_asyncio.py", line 2134, in run_sync_in_worker_thread
    return await future
           ^^^^^^^^^^^^
  File "C:\Users\Alaa\anaconda3\Lib\site-packages\anyio\_backends\_asyncio.py", line 851, in run
    result = context.run(func, *args)
             ^^^^^^^^^^^^^^^^^^^^^^^^
  File "C:\Users\Alaa\anaconda3\Lib\site-packages\chromadb\server\fastapi\__init__.py", line 606, in process_create_collection
    create = CreateCollection.model_validate(orjson.loads(raw_body))
             ^^^^^^^^^^^^^^^^^^^^^^^^^^^^^^^
AttributeError: type object 'CreateCollection' has no attribute 'model_validate'
[32mINFO[0m:     [10-05-2024 15:51:54] ::1:2288 - "POST /api/v1/collections?tenant=default_tenant&database=default_database HTTP/1.1" 500
[32mINFO[0m:     [10-05-2024 15:56:19] ::1:2361 - "GET /api/v1/tenants/default_tenant HTTP/1.1" 200
[32mINFO[0m:     [10-05-2024 15:56:19] ::1:2361 - "GET /api/v1/databases/default_database?tenant=default_tenant HTTP/1.1" 200
[31mERROR[0m:    [10-05-2024 15:56:21] type object 'CreateCollection' has no attribute 'model_validate'
Traceback (most recent call last):
  File "C:\Users\Alaa\anaconda3\Lib\site-packages\anyio\streams\memory.py", line 97, in receive
    return self.receive_nowait()
           ^^^^^^^^^^^^^^^^^^^^^
  File "C:\Users\Alaa\anaconda3\Lib\site-packages\anyio\streams\memory.py", line 92, in receive_nowait
    raise WouldBlock
anyio.WouldBlock

During handling of the above exception, another exception occurred:

Traceback (most recent call last):
  File "C:\Users\Alaa\anaconda3\Lib\site-packages\starlette\middleware\base.py", line 159, in call_next
    message = await recv_stream.receive()
              ^^^^^^^^^^^^^^^^^^^^^^^^^^^
  File "C:\Users\Alaa\anaconda3\Lib\site-packages\anyio\streams\memory.py", line 112, in receive
    raise EndOfStream
anyio.EndOfStream

During handling of the above exception, another exception occurred:

Traceback (most recent call last):
  File "C:\Users\Alaa\anaconda3\Lib\site-packages\chromadb\server\fastapi\__init__.py", line 78, in catch_exceptions_middleware
    return await call_next(request)
           ^^^^^^^^^^^^^^^^^^^^^^^^
  File "C:\Users\Alaa\anaconda3\Lib\site-packages\starlette\middleware\base.py", line 165, in call_next
    raise app_exc
  File "C:\Users\Alaa\anaconda3\Lib\site-packages\starlette\middleware\base.py", line 151, in coro
    await self.app(scope, receive_or_disconnect, send_no_error)
  File "C:\Users\Alaa\anaconda3\Lib\site-packages\starlette\middleware\base.py", line 189, in __call__
    with collapse_excgroups():
  File "C:\Users\Alaa\anaconda3\Lib\contextlib.py", line 158, in __exit__
    self.gen.throw(typ, value, traceback)
  File "C:\Users\Alaa\anaconda3\Lib\site-packages\starlette\_utils.py", line 93, in collapse_excgroups
    raise exc
  File "C:\Users\Alaa\anaconda3\Lib\site-packages\starlette\middleware\base.py", line 191, in __call__
    response = await self.dispatch_func(request, call_next)
               ^^^^^^^^^^^^^^^^^^^^^^^^^^^^^^^^^^^^^^^^^^^^
  File "C:\Users\Alaa\anaconda3\Lib\site-packages\chromadb\server\fastapi\__init__.py", line 92, in check_http_version_middleware
    return await call_next(request)
           ^^^^^^^^^^^^^^^^^^^^^^^^
  File "C:\Users\Alaa\anaconda3\Lib\site-packages\starlette\middleware\base.py", line 165, in call_next
    raise app_exc
  File "C:\Users\Alaa\anaconda3\Lib\site-packages\starlette\middleware\base.py", line 151, in coro
    await self.app(scope, receive_or_disconnect, send_no_error)
  File "C:\Users\Alaa\anaconda3\Lib\site-packages\starlette\middleware\exceptions.py", line 65, in __call__
    await wrap_app_handling_exceptions(self.app, conn)(scope, receive, send)
  File "C:\Users\Alaa\anaconda3\Lib\site-packages\starlette\_exception_handler.py", line 64, in wrapped_app
    raise exc
  File "C:\Users\Alaa\anaconda3\Lib\site-packages\starlette\_exception_handler.py", line 53, in wrapped_app
    await app(scope, receive, sender)
  File "C:\Users\Alaa\anaconda3\Lib\site-packages\starlette\routing.py", line 756, in __call__
    await self.middleware_stack(scope, receive, send)
  File "C:\Users\Alaa\anaconda3\Lib\site-packages\starlette\routing.py", line 776, in app
    await route.handle(scope, receive, send)
  File "C:\Users\Alaa\anaconda3\Lib\site-packages\starlette\routing.py", line 297, in handle
    await self.app(scope, receive, send)
  File "C:\Users\Alaa\anaconda3\Lib\site-packages\starlette\routing.py", line 77, in app
    await wrap_app_handling_exceptions(app, request)(scope, receive, send)
  File "C:\Users\Alaa\anaconda3\Lib\site-packages\starlette\_exception_handler.py", line 64, in wrapped_app
    raise exc
  File "C:\Users\Alaa\anaconda3\Lib\site-packages\starlette\_exception_handler.py", line 53, in wrapped_app
    await app(scope, receive, sender)
  File "C:\Users\Alaa\anaconda3\Lib\site-packages\starlette\routing.py", line 72, in app
    response = await func(request)
               ^^^^^^^^^^^^^^^^^^^
  File "C:\Users\Alaa\anaconda3\Lib\site-packages\fastapi\routing.py", line 278, in app
    raw_response = await run_endpoint_function(
                   ^^^^^^^^^^^^^^^^^^^^^^^^^^^^
  File "C:\Users\Alaa\anaconda3\Lib\site-packages\fastapi\routing.py", line 191, in run_endpoint_function
    return await dependant.call(**values)
           ^^^^^^^^^^^^^^^^^^^^^^^^^^^^^^
  File "C:\Users\Alaa\anaconda3\Lib\site-packages\chromadb\telemetry\opentelemetry\__init__.py", line 130, in wrapper
    return await f(*args, **kwargs)
           ^^^^^^^^^^^^^^^^^^^^^^^^
  File "C:\Users\Alaa\anaconda3\Lib\site-packages\chromadb\server\fastapi\__init__.py", line 630, in create_collection
    await to_thread.run_sync(
  File "C:\Users\Alaa\anaconda3\Lib\site-packages\anyio\to_thread.py", line 56, in run_sync
    return await get_async_backend().run_sync_in_worker_thread(
           ^^^^^^^^^^^^^^^^^^^^^^^^^^^^^^^^^^^^^^^^^^^^^^^^^^^^
  File "C:\Users\Alaa\anaconda3\Lib\site-packages\anyio\_backends\_asyncio.py", line 2134, in run_sync_in_worker_thread
    return await future
           ^^^^^^^^^^^^
  File "C:\Users\Alaa\anaconda3\Lib\site-packages\anyio\_backends\_asyncio.py", line 851, in run
    result = context.run(func, *args)
             ^^^^^^^^^^^^^^^^^^^^^^^^
  File "C:\Users\Alaa\anaconda3\Lib\site-packages\chromadb\server\fastapi\__init__.py", line 606, in process_create_collection
    create = CreateCollection.model_validate(orjson.loads(raw_body))
             ^^^^^^^^^^^^^^^^^^^^^^^^^^^^^^^
AttributeError: type object 'CreateCollection' has no attribute 'model_validate'
[32mINFO[0m:     [10-05-2024 15:56:21] ::1:2363 - "POST /api/v1/collections?tenant=default_tenant&database=default_database HTTP/1.1" 500
[32mINFO[0m:     [10-05-2024 17:09:42] Shutting down
[32mINFO[0m:     [10-05-2024 17:09:42] Waiting for application shutdown.
[36mDEBUG[0m:    [10-05-2024 17:09:42] Stopping component System
[36mDEBUG[0m:    [10-05-2024 17:09:42] Stopping component SegmentAPI
[36mDEBUG[0m:    [10-05-2024 17:09:42] Stopping component LocalSegmentManager
[36mDEBUG[0m:    [10-05-2024 17:09:42] Stopping component Posthog
[36mDEBUG[0m:    [10-05-2024 17:09:42] Stopping component QuotaEnforcer
[36mDEBUG[0m:    [10-05-2024 17:09:42] Stopping component SqliteDB
[36mDEBUG[0m:    [10-05-2024 17:09:42] Stopping component OpenTelemetryClient
[32mINFO[0m:     [10-05-2024 17:09:42] Application shutdown complete.
[32mINFO[0m:     [10-05-2024 17:09:42] Finished server process [[36m21604[0m]
